Workbook

Sheet 方案
A1: 方案提报任务（截止到8月17日）
A2: 序号 | B2: 任务标题 | C2: 任务类型 | D2: 创建时间 | E2: 计划开始时间 | F2: 计划结束时间 | G2: 实际完成时间 | H2: 计划工时 | I2: 实际工时 | J2: 创建人 | K2: 当前进展 | L2: 项目状态 （进行中 / 已结项-签约 / 已结项-丢单 / 暂停） | M2: 丢单原因 （客户失联 / 选其他供应商 / 预算不足 / 需求不实 / 价格 / 交期 / 其他）
A3: 1 | B3: C00003352｜陈辉｜工业｜埃及4万吨料场项目｜方案V1（预算） | C3: 方案 | D3: 2026-07-21 14:19:20 | E3: 2026-07-21 14:11:00 | F3: 2026-07-24 19:00:00 | G3: 2026-07-24 17:10:52 | H3: 3.2天 | I3: 3.2天 | J3: 陈辉 | K3: =VLOOKUP(B3,[2]方案!$B:$K,10,FALSE) -> TCI预期拿到了埃及一港口的运营权，有计划建散料库，已报预算，还在规划阶段。 | L3: 进行中
A4: 2 | B4: C00007339｜陈辉｜工业｜韩国大宇3万吨磷矿粉项目｜方案V1 | 重点项目 | C4: 方案 | D4: 2026-07-14 17:43:28 | E4: 2026-07-15 08:00:00 | F4: 2026-07-17 17:00:00 | G4: 2026-07-17 17:07:49 | H4: 2.4天 | I4: 2.4天 | J4: 陈辉 | K4: =VLOOKUP(B4,[2]方案!$B:$K,10,FALSE) -> 大宇在土库曼化肥厂项目，仓型各种变化和多次报价后，目前最后一版是焊接仓的EPC。用户和大宇还在比较仓型。 | L4: 进行中
A5: 3 | B5: C00001305｜陈辉｜工业｜韩国Jeju-四套污泥仓｜方案V1 | C5: 方案 | D5: 2026-07-02 17:47:15 | E5: 2026-07-03 08:00:00 | F5: 2026-07-09 17:00:00 | G5: 2026-07-09 15:04:26 | H5: 6.4天 | I5: 6.3天 | J5: 陈辉 | K5: =VLOOKUP(B5,[2]方案!$B:$K,10,FALSE) -> kim小项目，设计完仓型，客户改计划不需要了。 | L5: 已结项-丢单 | M5: 客户调整计划
A6: 4 | B6: C00001305｜陈辉｜工业｜韩国welcron5套污泥仓｜方案V1 | C6: 方案 | D6: 2026-07-02 17:03:09 | E6: 2026-07-02 16:58:00 | F6: 2026-07-06 19:00:00 | G6: 2026-07-03 18:25:38 | H6: 4.1天 | I6: 1.1天 | J6: 陈辉 | K6: =VLOOKUP(B6,[2]方案!$B:$K,10,FALSE) -> kim小项目，设计完仓型，客户改计划不需要了。 | L6: 已结项-丢单 | M6: 客户调整计划
A7: 5 | B7: C00001305｜陈辉｜工业｜韩国140立方米 x 3套树脂仓｜方案V1 | C7: 方案 | D7: 2026-06-29 17:36:48 | E7: 2026-06-30 08:00:00 | F7: 2026-07-03 19:00:00 | G7: 2026-07-03 18:25:43 | H7: 3.5天 | I7: 3.5天 | J7: 陈辉 | K7: =VLOOKUP(B7,[2]方案!$B:$K,10,FALSE) -> 小项目，仅仓无设备，客户还在决策。 | L7: 暂停
A8: 6 | B8: C00002715｜陈辉｜工业｜塞拉利昂2个3万吨clinker项目｜方案V1 | 重点项目 | C8: 方案 | D8: 2026-06-22 11:34:22 | E8: 2026-06-22 11:28:00 | F8: 2026-06-26 19:00:00 | G8: 2026-06-26 17:46:47 | H8: 4.3天 | I8: 4.3天 | J8: 陈辉 | K8: =VLOOKUP(B8,[2]方案!$B:$K,10,FALSE) -> 已去拜访客户，客户想法很多，缺资金。 | L8: 进行中
A9: 7 | B9: C00009463｜陈辉｜粮食｜突尼斯粮仓6x5,000t+10x8,000t｜方案V1 | C9: 方案 | D9: 2026-06-22 11:26:51 | E9: 2026-06-22 11:06:00 | F9: 2026-07-06 19:00:00 | G9: 2026-07-06 20:16:53 | H9: 14.3天 | I9: 14.4天 | J9: 陈辉 | K9: =VLOOKUP(B9,[2]方案!$B:$K,10,FALSE) -> 突尼斯一家工程公司想建这几个粮仓，没有资金，要靠国外银行给贷款，介绍了TCI给他们。项目还在找钱的阶段。 | L9: 进行中
A10: 8 | B10: C00001305｜陈辉｜工业｜韩国3,000立方米 x 2套石膏粉仓｜方案V2 | C10: 方案 | D10: 2026-05-27 11:38:18 | E10: 2026-05-27 11:27:00 | F10: 2026-07-02 19:29:00 | G10: 2026-07-02 18:33:52 | H10: 36.4天 | I10: 36.3天 | J10: 陈辉 | K10: =VLOOKUP(B10,[2]方案!$B:$K,10,FALSE) -> EPC，我方首次报价50Wusd，优化后及打折后价格42Wusd，业主说当地供应商报价32Wusd，且不需额外任何进口税费和运输费 | L10: 已结项-丢单 | M10: 选其他供应商 / 价格
A11: 9 | B11: C00009287｜陈辉｜工业｜大宇8套磷矿粉平底仓卸料｜方案V1 | C11: 方案 | D11: 2026-05-20 10:11:13 | E11: 2026-05-20 10:06:00 | F11: 2026-05-22 19:00:00 | G11: 2026-05-21 18:21:34 | H11: 2.4天 | I11: 1.4天 | J11: 陈辉 | K11: =VLOOKUP(B11,[2]方案!$B:$K,10,FALSE) -> 大宇在土库曼化肥厂项目，筒仓的卸料分包给了韩国的一家公司DY，我们给DY报价，仅报一次，技术澄清比较多，DY如果中标大概率优选选我们。 | L11: 进行中
A12: 10 | B12: C00009244｜陈辉｜工业｜火车卸料项目｜方案V1 | C12: 方案 | D12: 2026-05-18 15:56:16 | E12: 2026-05-18 15:51:00 | F12: 2026-05-22 19:00:00 | G12: 2026-05-22 18:13:36 | H12: 4.2天 | I12: 4.1天 | J12: 陈辉 | K12: =VLOOKUP(B12,[2]方案!$B:$K,10,FALSE) -> 客户自有仓，让我们报火车卸料后进仓和出仓相关设备。 客户的项目仍在计划评审阶段。 | L12: 进行中
A13: 11 | B13: C00008995｜陈辉｜粮食｜韩国港口粮食输送项目｜方案V1 | C13: 方案 | D13: 2026-03-12 10:21:50 | E13: 2026-03-12 10:11:00 | F13: 2026-03-18 17:00:00 | G13: 2026-03-19 09:09:05 | H13: 6.3天 | I13: 6.10天 | J13: 陈辉 | K13: =VLOOKUP(B13,[2]方案!$B:$K,10,FALSE) -> Kim联系的一个项目，已暂停。 | L13: 暂停
A14: 12 | B14: C00008180｜陈辉｜工业｜Lanwa水泥混拌系统｜方案V1 | 重点项目 | C14: 方案 | D14: =VLOOKUP(B14,[1]Sheet1!$A:$D,4,FALSE) -> 2026-08-17 09:00:35 | J14: 陈辉 | K14: =VLOOKUP(B14,[2]方案!$B:$K,10,FALSE) -> 老客户，项目含3个仓+混拌（mixer客户从其他供应商订购），客户中国通，对中国钢材加工价格十万分的了解，仅允许报价有合理利润，超出会选其他供应商。 | L14: 进行中
A15: 13 | B15: C00006497｜陈辉｜粮食｜埃及面粉项目｜方案V1（仅仓和钢构） | C15: 方案 | D15: =VLOOKUP(B15,[1]Sheet1!$A:$D,4,FALSE) -> 2026-08-10 12:18:07 | J15: 陈辉 | K15: =VLOOKUP(B15,[2]方案!$B:$K,10,FALSE) -> 埃及总包的一个投标项目，我们报价配合其投标。 | L15: 进行中
A16: 14 | B16: C00009849｜陈辉｜工业｜埃及3万吨混凝土仓（存氧化铝）项目｜方案V1 | C16: 方案 | D16: =VLOOKUP(B16,[1]Sheet1!$A:$D,4,FALSE) -> 2026-08-06 16:32:58 | J16: 陈辉 | K16: =VLOOKUP(B16,[2]方案!$B:$K,10,FALSE) -> 埃及的建筑公司作为投标人之一，向铝厂投标。 | L16: 进行中
A17: 15 | B17: C00009244｜陈辉｜工业｜巴西钢板仓和卸到火车项目｜方案V1 | C17: 方案 | D17: =VLOOKUP(B17,[1]Sheet1!$A:$D,4,FALSE) -> 2026-08-06 15:14:14 | J17: 陈辉 | K17: =VLOOKUP(B17,[2]方案!$B:$K,10,FALSE) -> 规划阶段，客户未来可能有两万吨粘土仓的需求，目前只是了解仓型和价格。 | L17: 进行中
A18: 16 | B18: C00009852｜陈辉｜工业｜澳洲8x6000t水泥装配仓｜方案V1（钢构量） | C18: 方案 | D18: =VLOOKUP(B18,[1]Sheet1!$A:$D,4,FALSE) -> 2026-07-31 15:23:27 | J18: 陈辉 | K18: =VLOOKUP(B18,[2]方案!$B:$K,10,FALSE) -> 预算。客户仍在评估是建造混凝土仓or钢板仓。 | L18: 进行中
A19: 17 | B19: C00003392｜陈辉｜工业｜莱歇6个热镀锌仓项目｜方案V1（钢构量） | C19: 方案 | D19: =VLOOKUP(B19,[1]Sheet1!$A:$D,4,FALSE) -> 2026-07-30 17:02:11 | J19: 陈辉 | K19: =VLOOKUP(B19,[2]方案!$B:$K,10,FALSE) -> 莱歇在台北正在做的磨粉项目，这几个仓是原本是业主范围，现在想拿出来询价，来决定是分包给莱歇去做还是业主自己做。 莱歇要求足够低价。 | L19: 进行中
A20: 18 | B20: C00009556｜陈子凡｜工业｜蒙古TESO 4x2500水泥中转站｜方案V1 | C20: 方案 | D20: 2026-07-21 23:34:13 | E20: 2026-07-22 08:00:00 | F20: 2026-07-23 18:00:00 | G20: 2026-07-23 20:20:58 | H20: 1.4天 | I20: 1.6天 | J20: 陈子凡 | K20: 给客户发了方案，待更新报价。准备报价中，但客户主业是食品，本次询价可能只是为了解投资预算。 8月份在蒙古期间约客户见面，客户见面意愿不强 | L20: 进行中
A21: 19 | B21: C00009734｜陈子凡｜粮食｜ 阿根廷6个面粉仓+3个润麦仓+1个麸皮仓 单仓｜重量计算+清单 | C21: 方案 | D21: 2026-07-09 10:54:39 | E21: 2026-07-09 10:53:00 | F21: 2026-07-14 18:00:00 | G21: 2026-07-14 19:52:34 | H21: 5.3天 | I21: 5.4天 | J21: 陈子凡 | K21: 报过价了，希望不大。客户为工程公司，项目投标中，且对方对中国供应链很了解，价格非常敏感 | L21: 进行中
A22: 20 | B22: C00007248｜陈子凡｜工业｜厄瓜多尔塑料方仓项目｜清单 | C22: 方案 | D22: 2026-07-01 10:15:31 | E22: 2026-07-01 09:12:00 | F22: 2026-07-02 18:12:00 | G22: 2026-07-02 11:38:03 | H22: 1.4天 | I22: 1.2天 | J22: 陈子凡 | K22: 客户比价中。提交报价后等通知，本次报价相比1期项目有上涨，客户大概率会找新供应商比价 | L22: 进行中
A23: 21 | B23: XXXXX｜陈子凡｜粮食｜北京生物质颗粒装车仓｜方案V1 | 初步方案 | C23: 方案 | D23: 2026-06-29 15:10:49 | E23: 2026-06-29 15:08:00 | F23: 2026-07-01 18:00:00 | G23: 2026-07-01 15:23:00 | H23: 2.1天 | I23: 2.1天 | J23: 陈子凡 | K23: 跟进中。项目较前期，联系人在出差，需要过一段时间再联系 | L23: 进行中
A24: 22 | B24: C00007247｜陈子凡｜工业｜MAK砖厂现有气力输送系统更新项目 ｜方案V1 | 重点项目 | C24: 方案 | D24: 2026-05-25 09:48:58 | E24: 2026-05-25 09:46:00 | F24: 2026-05-27 17:00:00 | G24: 2026-05-27 12:17:32 | H24: 2.3天 | I24: 2.2天 | J24: 陈子凡 | K24: 报价中 | L24: 进行中，近期可成交
A25: 23 | B25: C00009223｜陈子凡｜粮食｜马来西亚益海大豆仓单仓｜图纸+算重量V1 | C25: 方案 | D25: 2026-05-18 16:19:49 | E25: 2026-05-18 16:18:00 | F25: 2026-05-19 12:59:00 | G25: 2026-05-19 13:05:11 | H25: 0.9天 | I25: 0.9天 | J25: 陈子凡 | K25: 项目取消。中间人告知工厂砍掉了此项预算，改为修复现有筒仓 | L25: 已结项-丢单 | M25: 预算不足
A26: 24 | B26: C00009104｜陈子凡｜工业｜MONCEMENT 3x2000水泥中转站｜方案V2 | 重点项目 | C26: 方案 | D26: 2026-05-11 15:26:14 | E26: 2026-06-16 11:10:00 | F26: 2026-06-16 20:07:00 | G26: 2026-06-16 18:32:38 | H26: 0.4天 | I26: 0.4天 | J26: 陈子凡 | K26: 更新方案中。拜访后按要求更新方案，有望近期落地 | L26: 进行中
A27: 25 | B27: Manila 01｜陈子凡｜工业｜菲律宾生力集团机场临建项目｜算量V1 | C27: 方案 | D27: 2026-04-30 12:25:51 | E27: 2026-04-30 12:19:00 | F27: 2026-05-07 19:00:00 | G27: 2026-05-18 18:22:46 | H27: 7.3天 | I27: 18.3天 | J27: 陈子凡 | K27: 未参与 | L27: 已结项-丢单 | M27: 项目要求EPC，本项目土建占比很高，最终未参与
A28: 26 | B28: Manila 01｜陈子凡｜粮食｜SMC SHIPPING 平方仓项目｜方案V1 | C28: 方案 | D28: 2026-04-27 11:55:47 | E28: 2026-05-06 11:33:00 | F28: 2026-05-06 17:39:00 | G28: 2026-05-06 15:19:00 | H28: 0.3天 | I28: 0.2天 | J28: 陈子凡 | K28: 价格高，客户买了别人的，可能是越南的，我们在钢结构厂房上没有竞争力 | L28: 已结项-丢单 | M28: 价格高
A29: 27 | B29: C00009101｜陈子凡｜工业｜毛里求斯塑料颗粒圆仓（铝仓，单仓）｜方案+清单V1 | C29: 方案 | D29: 2026-04-08 10:29:20 | E29: 2026-04-08 10:28:00 | F29: 2026-04-14 18:00:00 | G29: 2026-04-14 16:17:41 | H29: 6.3天 | I29: 6.3天 | J29: 陈子凡 | K29: 项目较小，放弃 | L29: 已结项-丢单 | M29: 项目体量很小，客户要求多，纠结我们是不是工厂，故放弃
A30: 28 | B30: C00008912 ｜陈子凡｜工业｜印度尼西亚碳酸钙仓｜方案+清单V1 | C30: 方案 | D30: 2026-03-17 11:14:18 | E30: 2026-04-09 18:11:00 | F30: 2026-04-14 20:59:00 | G30: 2026-04-16 14:19:14 | H30: 5.1天 | I30: 6.9天 | J30: 陈子凡 | K30: 项目小，放弃 | L30: 已结项-丢单 | M30: 客户体量非常小，纠结价格，后续放弃
A31: 29 | B31: 20260304 菲律宾生力集团 取料机报价 | C31: 方案 | D31: 2026-03-04 09:32:36 | E31: 2026-03-04 09:31:00 | F31: 2026-03-06 17:00:00 | G31: 2026-03-04 15:46:35 | H31: 2.3天 | I31: 0.3天 | J31: 陈子凡 | K31: 等授标通知 | L31: 进行中
A32: 30 | B32: 20260302 C00007247 MAK 陈子凡 2x150吨小仓方案 报价 | C32: 方案 | D32: 2026-03-02 14:26:18 | E32: 2026-03-02 14:24:00 | F32: 2026-03-04 12:00:00 | G32: 2026-03-04 11:57:28 | H32: 1.9天 | I32: 1.9天 | J32: 陈子凡 | K32: 已成交 | L32: 结项-签约
A33: 31 | B33: 20260206 陈子凡 南美3x1000/3X2000/3X2500吨水泥仓方案+清单 | C33: 方案 | D33: 2026-02-06 08:48:33 | E33: 2026-02-06 08:46:00 | F33: 2026-02-06 18:00:00 | G33: 2026-02-06 16:13:22 | H33: 0.4天 | I33: 0.4天 | J33: 陈子凡 | K33: 项目真实性存疑 | L33: 已结项-丢单 | M33: 北京中间商询价项目，真实性存疑，后续不再合作
A34: 32 | B34: 20260113陈子凡 巴基斯坦4000吨稻壳颗粒仓及上料系统 | C34: 方案 | D34: 2026-01-13 17:45:20 | E34: 2026-01-14 08:00:00 | F34: 2026-02-05 12:02:00 | G34: 2026-02-05 10:02:32 | H34: 22.2天 | I34: 22.1天 | J34: 陈子凡 | K34: 项目暂停 | L34: 暂停
A35: 33 | B35: Manila01｜陈子凡｜粮食｜菲律宾4x2000吨锥底仓｜清单V1 | 报价清单 | C35: 方案 | D35: =VLOOKUP(B35,[1]Sheet1!$A:$D,4,FALSE) -> 2026-08-13 17:28:50 | J35: =VLOOKUP(B35,[1]Sheet1!$A:$J,10,FALSE) -> 陈子凡 | K35: 已提交报价，等反馈。单仓项目，上周报价，等反馈。 | L35: 进行中
A36: 34 | B36: C00005424|崔阳|工业|Sibur塑料颗粒的气力输送项目|方案V1 | C36: 方案 | D36: 2026-07-22 16:16:47 | E36: 2026-07-22 16:18:00 | F36: 2026-07-26 16:00:00 | H36: 4天 | J36: 崔阳
A37: 35 | B37: C00006570|崔阳|工业|Powerz螺旋输送机采购|方案V1 | C37: 方案 | D37: 2026-07-21 10:32:54 | E37: 2026-07-23 08:00:00 | F37: 2026-07-24 17:00:00 | G37: 2026-07-23 17:05:11 | H37: 1.4天 | I37: 0.4天 | J37: 崔阳
A38: 36 | B38: C00006458 崔阳|工业|达涅利 辊道和步进梁项目 |方案V1 | C38: 方案 | D38: 2026-07-09 12:29:38 | E38: 2026-07-14 08:00:00 | F38: 2026-07-26 17:00:00 | H38: 12.4天 | J38: 崔阳
A39: 37 | B39: C00009596 崔阳|工业|乌克兰AIK-EKO 铜矿石筒仓项目 |方案V1 | C39: 方案 | D39: 2026-07-08 11:23:44 | E39: 2026-07-09 08:00:00 | F39: 2026-07-13 18:00:00 | G39: 2026-07-13 18:19:36 | H39: 4.4天 | I39: 4.5天 | J39: 崔阳
A40: 38 | B40: C00009055 崔阳|工业|CC7 Europe 化工回收项目 |方案V1 | C40: 方案 | D40: 2026-07-07 17:35:29 | E40: 2026-07-08 08:00:00 | F40: 2026-07-12 18:00:00 | G40: 2026-07-14 14:58:24 | H40: 4.4天 | I40: 6.3天 | J40: 崔阳
...
